<?xml version="1.0" ?>
<robot name="aidin8">

  <material name="black">
    <color rgba="0.0 0.0 0.0 1.0"/>
  </material>
  <material name="blue">
    <color rgba="0.0 0.0 0.8 1.0"/>
  </material>
  <material name="green">
    <color rgba="0.0 0.8 0.0 1.0"/>
  </material>
  <material name="grey">
    <color rgba="0.2 0.2 0.2 1.0"/>
  </material>
  <material name="silver">
    <color rgba="0.913725490196 0.913725490196 0.847058823529 1.0"/>
  </material>
  <material name="orange">
    <color rgba="1.0 0.423529411765 0.0392156862745 1.0"/>
  </material>
  <material name="brown">
    <color rgba="0.870588235294 0.811764705882 0.764705882353 1.0"/>
  </material>
  <material name="red">
    <color rgba="0.8 0.0 0.0 1.0"/>
  </material>
  <material name="yellow">
    <color rgba="0.8 0.8 0.0 1.0"/>
  </material>
  <material name="white">
    <color rgba="1.0 1.0 1.0 1.0"/>
  </material>

<!-- <link name="world"/>
   
  <joint name="world_joint" type="fixed">
    <child link="odom"/>
    <parent link="world"/>
    <origin xyz="0.0 0.0 0.3" rpy="0.0 0.0 0.0"/>
  </joint> -->
<!--////////////////////////////////   Odom    ////////////////////////////////-->
  
  <link name="odom"/>
   
  <joint name="odom_joint" type="fixed">
    <child link="body"/>
    <parent link="odom"/>
    <origin xyz="0.0 0 0.440" rpy="0.0 0 0.0"/>
  </joint>

<!--////////////////////////////////   Body    ////////////////////////////////-->
  <link name="body">
    <inertial>
      <mass value="12.3188555"/>
      <origin xyz="0.00142 -0.00222 -0.04319" rpy="0 0 0"/>
      <inertia ixx="0.1104557116459" ixy="0.0002742627834" ixz="-0.0007826805716" iyy="0.2925866863396" iyz="-0.0018014327089" izz="0.3259809298915"/>
    </inertial>
    <!-- <collision name="body_box_col">
      <origin xyz="0 0 0" rpy="0 0 0"/>
      <geometry>
        <box size="0.97714 0.324 0.215"/>
      </geometry>
    </collision> -->

    <collision name="body_frame_col1">
      <origin xyz="0.44915 0 0" rpy="0 0 0"/>
      <geometry>
        <box size="0.0795 0.324 0.215"/>
      </geometry>
    </collision>
    <collision name="body_frame_col2">
      <origin xyz="0 0 0" rpy="0 0 0"/>
      <geometry>
        <box size="0.31 0.388 0.215"/>
      </geometry>
    </collision>
    <collision name="body_frame_col3">
      <origin xyz="-0.44915 0 0" rpy="0 0 0"/>
      <geometry>
        <box size="0.0795 0.324 0.215"/>
      </geometry>
    </collision>
    <collision name="body_frame_col4">
      <origin xyz="0 0.119 0.085" rpy="0 1.57079 0"/>
      <geometry>
        <cylinder length="0.8348" radius="0.01"/>
      </geometry>
    </collision>
    <collision name="body_frame_col5">
      <origin xyz="0 -0.119 0.085" rpy="0 1.57079 0"/>
      <geometry>
        <cylinder length="0.8348" radius="0.01"/>
      </geometry>
    </collision>
    <collision name="body_frame_col6">
      <origin xyz="0 0.119 -0.085" rpy="0 1.57079 0"/>
      <geometry>
        <cylinder length="0.8348" radius="0.01"/>
      </geometry>
    </collision>
    <collision name="body_frame_col7">
      <origin xyz="0 -0.119 -0.085" rpy="0 1.57079 0"/>
      <geometry>
        <cylinder length="0.8348" radius="0.01"/>
      </geometry>
    </collision>

    <visual name="body_visual">
      <origin xyz="0 0 0" rpy="0 0 3.14159"/>
      <geometry>
        <mesh filename="package://aidin8_sim/meshes/aidin8_body_cover.STL" scale="1 1 1"/>
      </geometry>
      <material name="silver"/>
    </visual>
  </link>
  <gazebo reference="body">
    <material>Gazebo/DarkGrey</material>
  </gazebo>


<!--//////////////////////////////// RF LINKS /////////////////////////////////-->

  <link name="RF_scap">
    <inertial>
      <mass value="6.3549628"/>
      <origin xyz="2.22e-03 -7.00e-05 -3.49e-02" rpy="0 0 0"/>
      <inertia ixx="0.0268838092963" ixy="-0.0000090031909" ixz="0.0010319405579" iyy="0.0388589753376" iyz="0.0000168509340" izz="0.0189992476926"/>
    </inertial>
      <collision name="RF_scap_col1">
        <origin xyz="0 0 -0.0447" rpy="0 0 0"/>
        <geometry>
          <cylinder length="0.21941" radius="0.0595"/>
        </geometry>
      </collision>
      <collision name="RF_scap_col2">
        <origin xyz="-0.01 0 0" rpy="0 1.57079 0"/>
        <geometry>
          <cylinder length="0.20046" radius="0.0595"/>
        </geometry>
      </collision>
    <!-- <visual name="RF_scap_vis">
      <origin xyz="0 0 0" rpy="0 0 0"/>
      <geometry>
        <mesh filename="package://aidin8_sim/meshes/Leg_Scapular_RF_stp_v2.STL" scale="1 1 1"/>
      </geometry>
      <material name="black"/>
    </visual> -->
    <visual name="RF_scap_vis_cover">
      <origin xyz="0 0 0" rpy="0 0 0"/>
      <geometry>
        <mesh filename="package://aidin8_sim/meshes/sc_cover_RF.STL" scale="1 1 1"/>
      </geometry>
      <material name="black"/>
    </visual>
  </link>
  <gazebo reference="RF_scap">
    <material>Gazebo/DarkGrey</material>
  </gazebo>

  <link name="RF_hip">
    <inertial>
      <mass value="0.8592967"/>
      <origin xyz="1.75316e-01 -1.49727e-02 1.2510e-04" rpy="0 0 0"/>
      <inertia ixx="0.0007326198866" ixy="0.0000038940144" ixz="-0.0000188175364" iyy="0.0157450190455" iyz="0.0000015777233" izz="0.0157308802469"/>
    </inertial>
    <collision name="RF_hip_col1">
      <origin xyz="0 0 0" rpy="0 0 0"/>
      <geometry>
        <cylinder length="0.081" radius="0.058"/>
      </geometry>
    </collision>
    <collision name="RF_hip_col2">
      <origin xyz="0.19150895 -0.02201 0" rpy="0 0 0"/>
      <geometry>
        <box size="0.3830179 0.07198 0.081"/>
      </geometry>
    </collision>
    <!-- <visual name="RF_hip_vis">
      <origin xyz="0 0 0" rpy="0 0 0"/>
      <geometry>
        <mesh filename="package://aidin8_sim/meshes/Leg_Hip_right_stp.STL" scale="1 1 1"/>
      </geometry>
      <material name="black"/>
    </visual> -->
    <visual name="RF_hip_vis_cover">
      <origin xyz="0 0 0" rpy="0 0 0"/>
      <geometry>
        <mesh filename="package://aidin8_sim/meshes/hip_cover_r.STL" scale="1 1 1"/>
      </geometry>
      <material name="black"/>
    </visual>
  </link>
  <gazebo reference="RF_hip">
    <material>Gazebo/DarkGrey</material>
  </gazebo>

  <link name="RF_knee">
    <inertial>
      <mass value="1.0798094"/>
      <origin xyz="0.1800139 0.0211379 0" rpy="0 0 0"/>
      <inertia ixx="0.0011170724779" ixy="0.0013927896194" ixz="-0.0000000006471" iyy="0.028702148538" iyz="-0.0000000000318" izz="0.0294755353979"/>
    </inertial>
    <collision name="RF_knee_col1">
      <origin xyz="0.012 -0.008 0" rpy="0 0 -0.3513" />
      <geometry>
        <box size="0.06567 0.045 0.036"/>
      </geometry>
    </collision>
    <collision name="RF_knee_col2">
      <origin xyz="0.132 0.0145 0" rpy="0 0 0.3513"/>
      <geometry>
        <box size="0.22 0.035 0.036"/>
      </geometry>
    </collision>
    <collision name="RF_knee_col3">
      <origin xyz="0.255 0.055 0" rpy="0 0 0.06" />
      <geometry>
        <box size="0.05 0.032 0.036"/>
      </geometry>
    </collision>
    <collision name="RF_knee_col4">
      <origin xyz="0.34 0.03 0" rpy="0 0 -0.38153"/>
      <geometry>
        <box size="0.15 0.035 0.036"/>
      </geometry>
    </collision> -->
    <visual name="RF_knee_vis">
      <origin xyz="0 0 0" rpy="0 0 0"/>
      <geometry>
        <mesh filename="package://aidin8_sim/meshes/leg_foot.STL" scale="1 1 1"/>
      </geometry>
      <material name="grey"/>
    </visual>
  </link>
  <gazebo reference="RF_knee">
    <material>Gazebo/Grey</material>
  </gazebo>

  <link name="RF_foot">
    <inertial>
      <mass value="0.01"/>
      <inertia ixx="0" ixy="0.0" ixz="0.0" iyy="0" iyz="0.0" izz="0"/>
    </inertial>
    <collision name="RF_foot_col1">
      <origin rpy="0  0  0" xyz="0.011  -0.007  0"/>
      <geometry>
        <sphere radius="0.04"/>
      </geometry>
      <!-- <surface>
      <friction>
        <ode>
          <mu>100000</mu>   coefficient of friction
          <mu2>100000</mu2> optional tangential coefficient of friction
        </ode>
      </friction>
      <restitution>
        <ode>
          <epsilon>0</epsilon> coefficient of restitution
        </ode>
      </restitution>
      <contact>
        <ode>
          <soft_cfm>1</soft_cfm> contact stiffness
          <soft_erp>1000000000</soft_erp>  contact damping
        </ode>
      </contact>
    </surface> -->
    </collision>
  </link>

<!--//////////////////////////////// RF JOINTS ////////////////////////////////-->

  <joint name="RFJ_scap" type="revolute">
    <parent link="body"/>
    <child link="RF_scap"/>
    <origin xyz="0.3224 -0.119   0" rpy="-1.57079  0      -1.57079"/>
    <axis xyz="0 0 1"/>
    <limit lower="-0.6108652382" upper="0.6108652382" effort="200.0" velocity="9"/>
    <dynamics damping="3"/>
  </joint>

  <joint name="RFJ_hip" type="revolute">
    <parent link="RF_scap"/>
    <child link="RF_hip"/>
    <origin xyz="0.13769 0      0" rpy="-1.58259  1.57079 -1.58259"/>
    <axis xyz="0 0 1"/>
    <limit lower="-3.14" upper="3.14" effort="200.0" velocity="9"/>
    <dynamics damping="3"/>
  </joint>

  <joint name="RFJ_knee" type="revolute">
    <parent link="RF_hip"/>
    <child link="RF_knee"/>
    <origin xyz="0.35 0   0" rpy="0      0      1.57079"/>
    <axis xyz="0 0 1"/>
    <limit lower="-1.308996939" upper="1.0471975512" effort="200.0" velocity="9"/>
    <dynamics damping="3"/>
  </joint>

  <joint name="RFJ_foot" type="fixed" dont_collapse="true"> <!--revolute -> fixed-->
    <parent link="RF_knee"/>
    <child link="RF_foot"/>
    <origin rpy="0 0 0" xyz="0.4 0 0"/>
    <axis xyz="0 0 1"/>
  </joint>

<!--//////////////////////////////// LF LINKS /////////////////////////////////-->

  <link name="LF_scap">
    <inertial>
      <mass value="6.3549628"/>
      <origin xyz="0.00223 -0.00011 -0.03491" rpy="0 0 0"/>
      <inertia ixx="0.0268822823205" ixy="0.0000315138420" ixz="-0.0010398645982" iyy="0.0388571979436" iyz="-0.0000013704590" izz="0.01899889911081"/>
    </inertial>
      <collision name="LF_scap_col1">
        <origin xyz="0 0 -0.0447" rpy="0 0 0"/>
        <geometry>
          <cylinder length="0.21941" radius="0.0595"/>
        </geometry>
      </collision>
      <collision name="LF_scap_col2">
        <origin xyz="-0.01 0 0" rpy="0 1.57079 0"/>
        <geometry>
          <cylinder length="0.20046" radius="0.0595"/>
        </geometry>
      </collision>
    <!-- <visual name="LF_scap_vis">
      <origin xyz="0 0 0" rpy="0 0 0"/>
      <geometry>
        <mesh filename="package://aidin8_sim/meshes/Leg_Scapular_LF_stp_v2.STL" scale="1 1 1"/>
      </geometry>
      <material name="black"/>
    </visual> -->
    <visual name="LF_scap_vis_cover">
      <origin xyz="0 0 0" rpy="0 0 0"/>
      <geometry>
        <mesh filename="package://aidin8_sim/meshes/sc_cover_LF.STL" scale="1 1 1"/>
      </geometry>
      <material name="black"/>
    </visual>
  </link>
  <gazebo reference="LF_scap">
    <material>Gazebo/DarkGrey</material>
  </gazebo>

  <link name="LF_hip">
    <inertial>
      <mass value="0.8592967"/>
      <origin xyz="1.75316e-01 -1.49727e-02 -1.2510e-04" rpy="0 0 0"/>
      <inertia ixx="0.0007326198857" ixy="0.0000038940144" ixz="0.0000188178556" iyy="0.0157450190446" iyz="-0.0000015777889" izz="0.0157308802467"/>
    </inertial>
    <collision name="LF_hip_col1">
      <origin xyz="0 0 0" rpy="0 0 0"/>
      <geometry>
        <cylinder length="0.081" radius="0.058"/>
      </geometry>
    </collision>
    <collision name="LF_hip_col2">
      <origin xyz="0.19150895 -0.02201 0" rpy="0 0 0"/>
      <geometry>
        <box size="0.3830179 0.07198 0.081"/>
      </geometry>
    </collision>
    <!-- <visual name="LF_hip_vis">
      <origin xyz="0 0 0" rpy="0 0 0"/>
      <geometry>
        <mesh filename="package://aidin8_sim/meshes/Leg_Hip_left_stp.STL" scale="1 1 1"/>
      </geometry>
      <material name="black"/>
    </visual> -->
    <visual name="LF_hip_vis_cover">
      <origin xyz="0 0 0" rpy="0 0 0"/>
      <geometry>
        <mesh filename="package://aidin8_sim/meshes/hip_cover_l.STL" scale="1 1 1"/>
      </geometry>
      <material name="black"/>
    </visual>
  </link>
  <gazebo reference="LF_hip">
    <material>Gazebo/DarkGrey</material>
  </gazebo>

  <link name="LF_knee">
    <inertial>
      <mass value="1.0798094"/>
      <origin xyz="0.1800139 0.0211379 0" rpy="0 0 0"/>
      <inertia ixx="0.0011170724779" ixy="0.0013927896194" ixz="-0.0000000006471" iyy="0.028702148538" iyz="-0.0000000000318" izz="0.0294755353979"/>
    </inertial>
    <collision name="LF_knee_col1">
      <origin xyz="0.012 -0.008 0" rpy="0 0 -0.3513" />
      <geometry>
        <box size="0.06567 0.045 0.036"/>
      </geometry>
    </collision>
    <collision name="LF_knee_col2">
      <origin xyz="0.132 0.0145 0" rpy="0 0 0.3513"/>
      <geometry>
        <box size="0.22 0.035 0.036"/>
      </geometry>
    </collision>
    <collision name="LF_knee_col3">
      <origin xyz="0.255 0.055 0" rpy="0 0 0.06" />
      <geometry>
        <box size="0.05 0.032 0.036"/>
      </geometry>
    </collision>
    <collision name="LF_knee_col4">
      <origin xyz="0.34 0.03 0" rpy="0 0 -0.38153"/>
      <geometry>
        <box size="0.15 0.035 0.036"/>
      </geometry>
    </collision> -->
    <visual name="LF_knee_vis">
      <origin xyz="0 0 0" rpy="0 0 0"/>
      <geometry>
        <mesh filename="package://aidin8_sim/meshes/leg_foot.STL" scale="1 1 1"/>
      </geometry>
      <material name="grey"/>
    </visual>
  </link>
  <gazebo reference="LF_knee">
    <material>Gazebo/Grey</material>
  </gazebo>

  <link name="LF_foot">
    <inertial>
      <mass value="0.01"/>
      <inertia ixx="0" ixy="0.0" ixz="0.0" iyy="0" iyz="0.0" izz="0"/>
    </inertial>
    <collision name="LF_foot_col1">
      <origin rpy="0  0  0" xyz="0.011  -0.007  0"/>
      <geometry>
        <sphere radius="0.04"/>
      </geometry>
      <!-- <surface>
      <friction>
        <ode>
          <mu>100000</mu>   coefficient of friction
          <mu2>100000</mu2> optional tangential coefficient of friction
        </ode>
      </friction>
      <restitution>
        <ode>
          <epsilon>0</epsilon> coefficient of restitution
        </ode>
      </restitution>
      <contact>
        <ode>
          <soft_cfm>1</soft_cfm> contact stiffness
          <soft_erp>1000000000</soft_erp>  contact damping
        </ode>
      </contact
    </surface> -->
    </collision>
  </link>

<!--//////////////////////////////// LF JOINTS ////////////////////////////////-->

  <joint name="LFJ_scap" type="revolute">
    <parent link="body"/>
    <child link="LF_scap"/>
    <origin xyz="0.3224 0.119  0" rpy="1.57079 0      1.57079"/>
    <axis xyz="0 0 1"/>
    <limit lower="-0.6108652382" upper="0.6108652382" effort="200.0" velocity="9"/>
    <dynamics damping="3"/>
  </joint>

  <joint name="LFJ_hip" type="revolute">
    <parent link="LF_scap"/>
    <child link="LF_hip"/>
    <origin xyz="0.13769 0      0" rpy="-1.559    1.57079  1.58259"/>
    <axis xyz="0 0 1"/>
    <limit lower="-3.14" upper="3.14" effort="200.0" velocity="9"/>
    <dynamics damping="3"/>
  </joint>

  <joint name="LFJ_knee" type="revolute">
    <parent link="LF_hip"/>
    <child link="LF_knee"/>
    <origin xyz="0.35 0   0" rpy="0      0      1.57079"/>
    <axis xyz="0 0 1"/>
    <limit lower="-1.308996939" upper="1.0471975512" effort="200.0" velocity="9"/>
    <dynamics damping="3"/>
  </joint>

  <joint name="LFJ_foot" type="fixed" dont_collapse="true"> <!--revolute -> fixed-->
    <origin rpy="0 0 0" xyz="0.4 0 0"/>
    <parent link="LF_knee"/>
    <child link="LF_foot"/>
  </joint>

<!--//////////////////////////////// LB LINKS /////////////////////////////////-->

  <link name="LB_scap">
    <inertial>
      <mass value="6.3549628"/>
      <origin xyz="2.22e-03 -7.00e-05  3.49e-02" rpy="0 0 0"/>
      <inertia ixx="0.0268838092963" ixy="0.0000090031909" ixz="-0.0010319405579" iyy="0.0388589753376" iyz="0.0000168509340" izz="0.0189992476926"/>
    </inertial>
    <collision name="LB_scap_col1">
        <origin xyz="0 0 0.0447" rpy="0 0 0"/>
        <geometry>
          <cylinder length="0.21941" radius="0.0595"/>
        </geometry>
      </collision>
      <collision name="LB_scap_col2">
        <origin xyz="-0.01 0 0" rpy="0 1.57079 0"/>
        <geometry>
          <cylinder length="0.20046" radius="0.0595"/>
        </geometry>
      </collision>
    <!-- <visual name="LB_scap_vis">
      <origin xyz="0 0 0" rpy="0 0 0"/>
      <geometry>
        <mesh filename="package://aidin8_sim/meshes/Leg_Scapular_LR_stp_v2.STL" scale="1 1 1"/>
      </geometry>
      <material name="black"/>
    </visual> -->
    <visual name="LB_scap_vis_cover">
      <origin xyz="0 0 0" rpy="0 0 0"/>
      <geometry>
        <mesh filename="package://aidin8_sim/meshes/sc_cover_LB.STL" scale="1 1 1"/>
      </geometry>
      <material name="black"/>
    </visual>
  </link>
  <gazebo reference="LB_scap">
    <material>Gazebo/DarkGrey</material>
  </gazebo>

  <link name="LB_hip">
    <inertial>
      <mass value="0.8592967"/>
      <origin xyz="1.75316e-01 -1.49727e-02 -1.2510e-04" rpy="0 0 0"/>
      <inertia ixx="0.0007326198857" ixy="0.0000038940144" ixz="0.0000188178556" iyy="0.0157450190446" iyz="-0.0000015777889" izz="0.0157308802467"/>
    </inertial>
    <collision name="LB_hip_col1">
      <origin xyz="0 0 0" rpy="0 0 0"/>
      <geometry>
        <cylinder length="0.081" radius="0.058"/>
      </geometry>
    </collision>
    <collision name="LB_hip_col2">
      <origin xyz="0.19150895 -0.02201 0" rpy="0 0 0"/>
      <geometry>
        <box size="0.3830179 0.07198 0.081"/>
      </geometry>
    </collision>
    <!-- <visual name="LB_hip_vis">
      <origin xyz="0 0 0" rpy="0 0 0"/>
      <geometry>
        <mesh filename="package://aidin8_sim/meshes/Leg_Hip_left_stp.STL" scale="1 1 1"/>
      </geometry>
      <material name="black"/>
    </visual> -->
    <visual name="LB_hip_vis_cover">
      <origin xyz="0 0 0" rpy="0 0 0"/>
      <geometry>
        <mesh filename="package://aidin8_sim/meshes/hip_cover_l.STL" scale="1 1 1"/>
      </geometry>
      <material name="black"/>
    </visual>
  </link>
  <gazebo reference="LB_hip">
    <material>Gazebo/DarkGrey</material>
  </gazebo>

  <link name="LB_knee">
    <inertial>
      <mass value="1.0798094"/>
      <origin xyz="0.1800139 0.0211379 0" rpy="0 0 0"/>
      <inertia ixx="0.0011170724779" ixy="0.0013927896194" ixz="-0.0000000006471" iyy="0.028702148538" iyz="-0.0000000000318" izz="0.0294755353979"/>
    </inertial>
    <collision name="LB_knee_col1">
      <origin xyz="0.012 -0.008 0" rpy="0 0 -0.3513" />
      <geometry>
        <box size="0.06567 0.045 0.036"/>
      </geometry>
    </collision>
    <collision name="LB_knee_col2">
      <origin xyz="0.132 0.0145 0" rpy="0 0 0.3513"/>
      <geometry>
        <box size="0.22 0.035 0.036"/>
      </geometry>
    </collision>
    <collision name="LB_knee_col3">
      <origin xyz="0.255 0.055 0" rpy="0 0 0.06" />
      <geometry>
        <box size="0.05 0.032 0.036"/>
      </geometry>
    </collision>
    <collision name="LB_knee_col4">
      <origin xyz="0.34 0.03 0" rpy="0 0 -0.38153"/>
      <geometry>
        <box size="0.15 0.035 0.036"/>
      </geometry>
    </collision> -->
    <visual name="LB_knee_vis">
      <origin xyz="0 0 0" rpy="0 0 0"/>
      <geometry>
        <mesh filename="package://aidin8_sim/meshes/leg_foot.STL" scale="1 1 1"/>
      </geometry>
      <material name="grey"/>
    </visual>
  </link>
  <gazebo reference="LB_knee">
    <material>Gazebo/Grey</material>
  </gazebo>

  <link name="LB_foot">
    <inertial>
      <mass value="0.01"/>
      <inertia ixx="0" ixy="0.0" ixz="0.0" iyy="0" iyz="0.0" izz="0"/>
    </inertial>
    <collision name="LB_foot_col1">
      <origin rpy="0  0  0" xyz="0.011  -0.007  0"/>
      <geometry>
        <sphere radius="0.04"/>
      </geometry>
    </collision>
  </link>

<!--//////////////////////////////// LB JOINTS ////////////////////////////////-->

  <joint name="LBJ_scap" type="revolute">
    <parent link="body"/>
    <child link="LB_scap"/>
    <origin xyz="-0.3224  0.119   0" rpy="1.57079 0      1.57079"/>
    <axis xyz="0 0 1"/>
    <limit lower="-0.6108652382" upper="0.6108652382" effort="200.0" velocity="9"/>
    <dynamics damping="3"/>
  </joint>

  <joint name="LBJ_hip" type="revolute">
    <parent link="LB_scap"/>
    <child link="LB_hip"/>
    <origin xyz="0.13769 0      0" rpy="-1.559    1.57079  1.58259"/>
    <axis xyz="0 0 1"/>
    <limit lower="-3.14" upper="3.14" effort="200.0" velocity="9"/>
    <dynamics damping="3"/>
  </joint>

  <joint name="LBJ_knee" type="revolute">
    <parent link="LB_hip"/>
    <child link="LB_knee"/>
    <origin xyz="0.35 0   0" rpy="0      0      1.57079"/>
    <axis xyz="0 0 1"/>
    <limit lower="-1.308996939" upper="1.0471975512" effort="200.0" velocity="9"/>
    <dynamics damping="3"/>
  </joint>

  <joint name="LBJ_foot" type="fixed" dont_collapse="true">
    <origin rpy="0 0 0" xyz="0.4 0 0"/>
    <parent link="LB_knee"/>
    <child link="LB_foot"/>
    <axis xyz="0 0 1"/>
  </joint>

<!--//////////////////////////////// RB LINKS /////////////////////////////////-->

  <link name="RB_scap">
    <inertial>
      <mass value="6.3549628"/>
      <origin xyz="0.00223 0.00011 0.03491" rpy="0 0 0"/>
      <inertia ixx="0.0268822823505" ixy="-0.0000315138420" ixz="-0.0010398645982" iyy="0.0388571979436" iyz="-0.0000013704590" izz="0.0189988991081"/>
    </inertial>
    <collision name="RB_scap_col1">
        <origin xyz="0 0 0.0447" rpy="0 0 0"/>
        <geometry>
          <cylinder length="0.21941" radius="0.0595"/>
        </geometry>
      </collision>
      <collision name="RB_scap_col2">
        <origin xyz="-0.01 0 0" rpy="0 1.57079 0"/>
        <geometry>
          <cylinder length="0.20046" radius="0.0595"/>
        </geometry>
      </collision>
    <!-- <visual name="RB_scap_vis">
      <origin xyz="0 0 0" rpy="0 0 0"/>
      <geometry>
        <mesh filename="package://aidin8_sim/meshes/Leg_Scapular_RR_stp_v2.STL" scale="1 1 1"/>
      </geometry>
      <material name="black"/>
    </visual> -->
    <visual name="RB_scap_vis_cover">
      <origin xyz="0 0 0" rpy="0 0 0"/>
      <geometry>
        <mesh filename="package://aidin8_sim/meshes/sc_cover_RB.STL" scale="1 1 1"/>
      </geometry>
      <material name="black"/>
    </visual>
  </link>
  <gazebo reference="RB_scap">
    <material>Gazebo/DarkGrey</material>
  </gazebo>

  <link name="RB_hip">
    <inertial>
      <mass value="0.8592967"/>
      <origin xyz="1.75316e-01 -1.49727e-02 1.2510e-04" rpy="0 0 0"/>
      <inertia ixx="0.0007326198866" ixy="0.0000038940144" ixz="-0.0000188175364" iyy="0.0157450190455" iyz="0.0000015777233" izz="0.0157308802469"/>
    </inertial>
    <collision name="RB_hip_col1">
      <origin xyz="0 0 0" rpy="0 0 0"/>
      <geometry>
        <cylinder length="0.081" radius="0.058"/>
      </geometry>
    </collision>
    <collision name="RB_hip_col2">
      <origin xyz="0.19150895 -0.02201 0" rpy="0 0 0"/>
      <geometry>
        <box size="0.3830179 0.07198 0.081"/>
      </geometry>
    </collision>
    <!-- <visual name="RB_hip_vis">
      <origin xyz="0 0 0" rpy="0 0 0"/>
      <geometry>
        <mesh filename="package://aidin8_sim/meshes/Leg_Hip_right_stp.STL" scale="1 1 1"/>
      </geometry>
      <material name="black"/>
    </visual> -->
    <visual name="RB_hip_vis_cover">
      <origin xyz="0 0 0" rpy="0 0 0"/>
      <geometry>
        <mesh filename="package://aidin8_sim/meshes/hip_cover_r.STL" scale="1 1 1"/>
      </geometry>
      <material name="black"/>
    </visual>
  </link>
  <gazebo reference="RB_hip">
    <material>Gazebo/DarkGrey</material>
  </gazebo>

  <link name="RB_knee">
    <inertial>
      <mass value="1.0798094"/>
      <origin xyz="0.1800139 0.0211379 0" rpy="0 0 0"/>
      <inertia ixx="0.0011170724779" ixy="0.0013927896194" ixz="-0.0000000006471" iyy="0.028702148538" iyz="-0.0000000000318" izz="0.0294755353979"/>
    </inertial>
    <collision name="RB_knee_col1">
      <origin xyz="0.012 -0.008 0" rpy="0 0 -0.3513" />
      <geometry>
        <box size="0.06567 0.045 0.036"/>
      </geometry>
    </collision>
    <collision name="RB_knee_col2">
      <origin xyz="0.132 0.0145 0" rpy="0 0 0.3513"/>
      <geometry>
        <box size="0.22 0.035 0.036"/>
      </geometry>
    </collision>
    <collision name="RB_knee_col3">
      <origin xyz="0.255 0.055 0" rpy="0 0 0.06" />
      <geometry>
        <box size="0.05 0.032 0.036"/>
      </geometry>
    </collision>
    <collision name="RB_knee_col4">
      <origin xyz="0.34 0.03 0" rpy="0 0 -0.38153"/>
      <geometry>
        <box size="0.15 0.035 0.036"/>
      </geometry>
    </collision> -->
    <visual name="RB_knee_vis">
      <origin xyz="0 0 0" rpy="0 0 0"/>
      <geometry>
        <mesh filename="package://aidin8_sim/meshes/leg_foot.STL" scale="1 1 1"/>
      </geometry>
      <material name="grey"/>
    </visual>
  </link>
  <gazebo reference="RB_knee">
    <material>Gazebo/Grey</material>
  </gazebo>

  <link name="RB_foot">
    <inertial>
      <mass value="0.01"/>
      <inertia ixx="0" ixy="0.0" ixz="0.0" iyy="0" iyz="0.0" izz="0"/>
    </inertial>
    <collision name="RB_foot_col1">
      <origin rpy="0  0  0" xyz="0.011  -0.007  0"/>
      <geometry>
        <sphere radius="0.04"/>
      </geometry>
    </collision>
  </link>

<!--//////////////////////////////// RB JOINTS ////////////////////////////////-->

  <joint name="RBJ_scap" type="revolute">
    <parent link="body"/>
    <child link="RB_scap"/>
    <origin xyz="-0.3224 -0.119   0" rpy="-1.57079  0      -1.57079"/>
    <axis xyz="0 0 1"/>
    <limit lower="-0.6108652382" upper="0.6108652382" effort="200.0" velocity="9"/>
    <dynamics damping="3"/>
  </joint>

  <joint name="RBJ_hip" type="revolute">
    <parent link="RB_scap"/>
    <child link="RB_hip"/>
    <origin xyz="0.13769 0      0" rpy="-1.58259  1.57079 -1.58259"/>
    <axis xyz="0 0 1"/>
    <limit lower="-3.14" upper="3.14" effort="200.0" velocity="9"/>
    <dynamics damping="3"/>
  </joint>

  <joint name="RBJ_knee" type="revolute">
    <parent link="RB_hip"/>
    <child link="RB_knee"/>
    <origin xyz="0.35 0   0" rpy="0      0      1.57079"/>
    <axis xyz="0 0 1"/>
    <limit lower="-1.308996939" upper="1.0471975512" effort="200.0" velocity="9"/>
    <dynamics damping="3"/>
  </joint>

  <joint name="RBJ_foot" type="fixed" dont_collapse="true">
    <origin rpy="0 0 0" xyz="0.4 0 0"/>
    <parent link="RB_knee"/>
    <child link="RB_foot"/>
    <axis xyz="0 0 1"/>
  </joint>

  <!-- <gazebo reference="RF_foot">
    <mu1>1</mu1>
    <mu2>1</mu2>
    <minDepth>0.01</minDepth>
    <kp  value="1000000"/>
    <kd  value="1000.0"/>
  </gazebo>

  <gazebo reference="LF_foot">
    <mu1>1</mu1>
    <mu2>1</mu2>
    <minDepth>0.01</minDepth>
      <kp  value="1000000"/>
    <kd  value="1000.0"/>
    
  </gazebo>

  <gazebo reference="LB_foot">
    <mu1>1</mu1>
    <mu2>1</mu2>
    <minDepth>0.01</minDepth>
      <kp  value="1000000"/>
    <kd  value="1000.0"/>
  </gazebo>

  <gazebo reference="RB_foot">
    <mu1>1</mu1>
    <mu2>1</mu2>
    <minDepth>0.01</minDepth>
      <kp  value="1000000"/>
    <kd  value="1000.0"/>
  </gazebo> -->

  <!-- <gazebo reference="RF_foot">
    <mu1>1.0</mu1>
    <mu2>1.0</mu2>
    <slip1>0</slip1>
    <slip2>0</slip2>
    <maxVel>0.01</maxVel>
    <minDepth>0.001</minDepth>
    <soft_cfm>0</soft_cfm>
    <soft_erp>0.2</soft_erp>
    <kp  value="1000000.0"/>
    <kd  value="100.0"/>
  </gazebo>

  <gazebo reference="LF_foot">
    <mu1>1.0</mu1>
    <mu2>1.0</mu2>
    <slip1>0</slip1>
    <slip2>0</slip2>
    <maxVel>0.01</maxVel>
    <minDepth>0.001</minDepth>
    <soft_cfm>0</soft_cfm>
    <soft_erp>0.2</soft_erp>
    <kp  value="1000000.0"/>
    <kd  value="100.0"/>
  </gazebo>

  <gazebo reference="LB_foot">
    <mu1>1.0</mu1>
    <mu2>1.0</mu2>
    <slip1>0</slip1>
    <slip2>0</slip2>
    <maxVel>0.01</maxVel>
    <minDepth>0.001</minDepth>
    <soft_cfm>0</soft_cfm>
    <soft_erp>0.2</soft_erp>
    <kp  value="1000000.0"/>
    <kd  value="100.0"/>
  </gazebo>

  <gazebo reference="RB_foot">
    <mu1>1.0</mu1>
    <mu2>1.0</mu2>
    <slip1>0</slip1>
    <slip2>0</slip2>
    <maxVel>0.01</maxVel>
    <minDepth>0.001</minDepth>
    <soft_cfm>0</soft_cfm>
    <soft_erp>0.2</soft_erp>
    <kp  value="1000000.0"/>
    <kd  value="100.0"/>
  </gazebo> -->


<!--//////////////////////////////// Sensor - Lidar //////////////////////////////////-->

  <joint name="lidar_joint" type='fixed'>
    <child link="lidar_link"/>
    <parent link="body" />
    <origin xyz="0 0 0.143" rpy="0 0 0" />
  </joint>

  <link name="lidar_link">
    <inertial>
      <mass value="0.001" /> 
      <origin xyz="0 0 0" rpy="0 0 0" />
      <inertia ixx="0.000241148" ixy="0.0" ixz="0.0" iyy="0.000241148" iyz="0.0" izz="0.000264"/>
    </inertial>
    <visual>
      <origin xyz="0 0 0" rpy="0 0 0" />
      <geometry>
        <mesh filename="package://aidin8_sim/meshes/ouster_os0.dae" />
      </geometry>
    </visual>
    <collision>
      <origin xyz="0 0 0" rpy="0 0 0" />
      <geometry>
        <cylinder radius="0.04" length="0.073" />
      </geometry>
    </collision>
  </link>

  <gazebo reference="lidar_link">
    <sensor type="gpu_ray" name="ouster-os0">
      <pose>0 0 0 0 0 0</pose>
      <visualize>false</visualize>
      <update_rate>20</update_rate>
      <ray>
        <scan>
          <horizontal>
            <samples>220</samples>
            <resolution>1</resolution>
            <min_angle>-3.14159</min_angle>
            <max_angle>3.14159</max_angle>
          </horizontal>
          <vertical>
            <samples>64</samples>
            <resolution>1</resolution>  
            <min_angle>-0.785</min_angle>
            <max_angle>0.785</max_angle>
          </vertical>
        </scan>
        <range>
          <min>0.3</min>
          <max>10</max>
          <resolution>0.001</resolution>
        </range>
        <noise>
          <type>gaussian</type>
          <mean>0.0</mean>
          <stddev>0.0</stddev>
        </noise>
      </ray>
      <plugin name="gazebo_ros_laser_controller" filename="libgazebo_ros_velodyne_gpu_laser.so">
        <topicName>ouster/points</topicName>
        <frameName>lidar_link</frameName>
        <min_range>0.3</min_range>
        <max_range>10</max_range>
        <gaussianNoise>0.008</gaussianNoise>
      </plugin>
    </sensor>
  </gazebo>


<!--//////////////////////////////// Sensor - Camera ////////////////////////////////-->
<!-- camera names -->
<!-- 

                              __1/2__
1. camera_upper               |     |
2. camera_lower               |     |
3. camera_left              3 |     | 5
4. camera_back                |     | 
5. camera_right               |_____|
                                 4
-->

<!--/////////////////////////////// Camera Upper //////////////////////////////////-->

  <joint name="camera_upper_joint_model" type="fixed">
      <child link="camera_upper_link_model"/>
      <parent link="body"/>
      <origin xyz="0.45860270559 0.0 -0.01415118549 " rpy="0.0 0.5026548245743669 0.0"/>
  </joint>
    
  <link name="camera_upper_link_model">
    <!-- <visual>
      <origin xyz="0 0 0" rpy="0 0 0" />
      <geometry>
        <mesh filename="package://aidin8_sim/meshes/realsense_d435i.STL" />
      </geometry>
    </visual> -->
  </link>

  <joint name="camera_upper_joint_per" type="fixed">
    <child link="camera_upper_link_per"/>
    <parent link="camera_upper_link_model"/>
    <origin xyz="0.02505 0.0 0.0" rpy="0.0 0.0 0.0"/>
  </joint>
    
  <link name="camera_upper_link_per"/>

  <joint name="camera_upper_joint_vis" type="fixed">
    <child link="camera_upper_link_vis"/>
    <parent link="camera_upper_link_per"/>
    <origin xyz="0.0 0.0 0.0" rpy="-1.57 0.0 -1.57"/>
  </joint>
    
  <link name="camera_upper_link_vis"/>
      
  <gazebo reference="camera_upper_link_per">
     <!--sensor name='camera_upper1' type='camera'>
        <camera name="head_upper1">
          <image>
            <width>64</width>
            <height>48</height>
          </image>
          <clip>
            <near>0.001</near>
            <far>300</far>
          </clip>
        </camera>
        <always_on>1</always_on>
        <update_rate>30.0</update_rate>
        <visualize>1</visualize>
        <plugin name="camera_upper_controller" filename="libgazebo_ros_camera.so">

          <alwaysOn>true</alwaysOn>
          <updateRate>0.0</updateRate>
          <cameraName>camera_upper1</cameraName>
          <imageTopicName>image_raw</imageTopicName>
          <cameraInfoTopicName>camera_info</cameraInfoTopicName>
          <frameName>/camera_upper_link_vis</frameName>
          <hackBaseLine>0.07</hackBaseLine>
          <distortionK1>0.0</distortionK1>
          <distortionK2>0.0</distortionK2>
          <distortionK3>0.0</distortionK3>
          <distortionT1>0.0</distortionT1>
          <distortionT2>0.0</distortionT2>
        </plugin>
      </sensor-->
    <sensor name='camera_upper' type='depth'>
      <camera name="camera_upper">
        <horizontal_fov>1.5184364492</horizontal_fov>
        <image>
          <width>160</width> 
          <height>120</height> 
        </image>
        <clip>
          <near>0.02</near>
          <far>300</far>
        </clip>
      </camera>
      <always_on>1</always_on>
      <update_rate>30.0</update_rate>
      <visualize>1</visualize>
      <plugin name="camera_upper_controller" filename="libgazebo_ros_openni_kinect.so">
        <robotNamespace></robotNamespace>
        <baseline>0.2</baseline>
        <alwaysOn>true</alwaysOn>
        <updateRate>30.0</updateRate>
        <cameraName>camera_upper</cameraName>
        <imageTopicName>image_raw</imageTopicName>
        <cameraInfoTopicName>camera_upper_info</cameraInfoTopicName>
        <depthImageTopicName>image_raw</depthImageTopicName>
        <depthImageInfoTopicName>camera_upper_info</depthImageInfoTopicName>
        <pointCloudTopicName>points</pointCloudTopicName>
        <frameName>camera_upper_link_vis</frameName>
        <pointCloudCutoff>0.04</pointCloudCutoff>
        <distortionK1>0.0</distortionK1>
        <distortionK2>0.0</distortionK2>
        <distortionK3>0.0</distortionK3>
        <distortionT1>0.0</distortionT1>
        <distortionT2>0.0</distortionT2>
        <CxPrime>0</CxPrime>
        <Cx>0</Cx>
        <Cy>0</Cy>
        <focalLength>0</focalLength>
        <hackBaseline>0</hackBaseline>
      </plugin>
    </sensor>
  </gazebo>

<!--/////////////////////////////// Camera Lower //////////////////////////////////-->

  <joint name="camera_lower_joint_model" type="fixed">
      <child link="camera_lower_link_model"/>
      <parent link="body"/>
      <origin xyz="0.42882911 0.0 -0.0704022 " rpy="0.0 0.7853981633974483 0.0"/>
  </joint>
    
  <link name="camera_lower_link_model">
    <!-- <visual>
      <origin xyz="0 0 0" rpy="0 0 0" />
      <geometry>
        <mesh filename="package://aidin8_sim/meshes/realsense_d435i.STL" />
      </geometry>
    </visual> -->
  </link>

  <joint name="camera_lower_joint_per" type="fixed">
    <child link="camera_lower_link_per"/>
    <parent link="camera_lower_link_model"/>
    <origin xyz="0.02505 0.0 0.0" rpy="0.0 0.0 0.0"/>
  </joint>
    
  <link name="camera_lower_link_per"/>

  <joint name="camera_lower_joint_vis" type="fixed">
    <child link="camera_lower_link_vis"/>
    <parent link="camera_lower_link_per"/>
    <origin xyz="0.0 0.0 0.0" rpy="-1.57 0.0 -1.57"/>
  </joint>
    
  <link name="camera_lower_link_vis"/>
      
  <gazebo reference="camera_lower_link_per">
  <!--sensor name='camera_lower1' type='camera'>
        <camera name="head_lower1">
          <image>
            <width>64</width>
            <height>48</height>
          </image>
          <clip>
            <near>0.001</near>
            <far>300</far>
          </clip>
        </camera>
        <always_on>1</always_on>
        <update_rate>30.0</update_rate>
        <visualize>1</visualize>
        <plugin name="camera_lower_controller" filename="libgazebo_ros_camera.so">

          <alwaysOn>true</alwaysOn>
          <updateRate>0.0</updateRate>
          <cameraName>camera_lower1</cameraName>
          <imageTopicName>image_raw</imageTopicName>
          <cameraInfoTopicName>camera_info</cameraInfoTopicName>
          <frameName>/camera_lower_link_vis</frameName>
          <hackBaseLine>0.07</hackBaseLine>
          <distortionK1>0.0</distortionK1>
          <distortionK2>0.0</distortionK2>
          <distortionK3>0.0</distortionK3>
          <distortionT1>0.0</distortionT1>
          <distortionT2>0.0</distortionT2>
        </plugin>
      </sensor-->
    <sensor name='camera_lower' type='depth'>
      <camera name="camera_lower">
        <horizontal_fov>1.5184364492</horizontal_fov>
        <image>
          <width>160</width> 
          <height>120</height> 
        </image>
        <clip>
          <near>0.02</near>
          <far>300</far>
        </clip>
      </camera>
      <always_on>1</always_on>
      <update_rate>30.0</update_rate>
      <visualize>1</visualize>
      <plugin name="camera_lower_controller" filename="libgazebo_ros_openni_kinect.so">
        <robotNamespace></robotNamespace>
        <baseline>0.2</baseline>
        <alwaysOn>true</alwaysOn>
        <updateRate>30.0</updateRate>
        <cameraName>camera_lower</cameraName>
        <imageTopicName>image_raw</imageTopicName>
        <cameraInfoTopicName>camera_lower_info</cameraInfoTopicName>
        <depthImageTopicName>image_raw</depthImageTopicName>
        <depthImageInfoTopicName>camera_lower_info</depthImageInfoTopicName>
        <pointCloudTopicName>points</pointCloudTopicName>
        <frameName>camera_lower_link_vis</frameName>
        <pointCloudCutoff>0.04</pointCloudCutoff>
        <distortionK1>0.0</distortionK1>
        <distortionK2>0.0</distortionK2>
        <distortionK3>0.0</distortionK3>
        <distortionT1>0.0</distortionT1>
        <distortionT2>0.0</distortionT2>
        <CxPrime>0</CxPrime>
        <Cx>0</Cx>
        <Cy>0</Cy>
        <focalLength>0</focalLength>
        <hackBaseline>0</hackBaseline>
      </plugin>
    </sensor>
  </gazebo>

<!--/////////////////////////////// Camera Left //////////////////////////////////-->

  <joint name="camera_left_joint_model" type="fixed">
      <child link="camera_left_link_model"/>
      <parent link="body"/>
      <origin xyz="-0.074 0.16720670557 -0.0086484888 " rpy="0.0 1.1344640137963142 1.5707963267948966"/>
  </joint>
    
  <link name="camera_left_link_model">
    <!-- <visual>
      <origin xyz="0 0 0" rpy="0 0 0" />
      <geometry>
        <mesh filename="package://aidin8_sim/meshes/realsense_d435i.STL" />
      </geometry>
    </visual> -->
  </link>

  <joint name="camera_left_joint_per" type="fixed">
    <child link="camera_left_link_per"/>
    <parent link="camera_left_link_model"/>
    <origin xyz="0.02505 0.0 0.0" rpy="0.0 0.0 0.0"/>
  </joint>
    
  <link name="camera_left_link_per"/>

  <joint name="camera_left_joint_vis" type="fixed">
    <child link="camera_left_link_vis"/>
    <parent link="camera_left_link_per"/>
    <origin xyz="0.0 0.0 0.0" rpy="-1.57 0.0 -1.57"/>
  </joint>
    
  <link name="camera_left_link_vis"/>
      
  <gazebo reference="camera_left_link_per">
 <!--sensor name='camera_left1' type='camera'>
        <camera name="head_left1">
          <image>
            <width>64</width>
            <height>48</height>
          </image>
          <clip>
            <near>0.001</near>
            <far>300</far>
          </clip>
        </camera>
        <always_on>1</always_on>
        <update_rate>30.0</update_rate>
        <visualize>1</visualize>
        <plugin name="camera_left_controller" filename="libgazebo_ros_camera.so">

          <alwaysOn>true</alwaysOn>
          <updateRate>0.0</updateRate>
          <cameraName>camera_left1</cameraName>
          <imageTopicName>image_raw</imageTopicName>
          <cameraInfoTopicName>camera_info</cameraInfoTopicName>
          <frameName>/camera_left_link_vis</frameName>
          <hackBaseLine>0.07</hackBaseLine>
          <distortionK1>0.0</distortionK1>
          <distortionK2>0.0</distortionK2>
          <distortionK3>0.0</distortionK3>
          <distortionT1>0.0</distortionT1>
          <distortionT2>0.0</distortionT2>
        </plugin>
      </sensor-->
    <sensor name='camera_left' type='depth'>
      <camera name="camera_left">
        <horizontal_fov>1.5184364492</horizontal_fov>
        <image>
          <width>160</width> 
          <height>120</height> 
        </image>
        <clip>
          <near>0.02</near>
          <far>300</far>
        </clip>
      </camera>
      <always_on>1</always_on>
      <update_rate>30.0</update_rate>
      <visualize>1</visualize>
      <plugin name="camera_left_controller" filename="libgazebo_ros_openni_kinect.so">
        <robotNamespace></robotNamespace>
        <baseline>0.2</baseline>
        <alwaysOn>true</alwaysOn>
        <updateRate>30.0</updateRate>
        <cameraName>camera_left</cameraName>
        <imageTopicName>image_raw</imageTopicName>
        <cameraInfoTopicName>camera_left_info</cameraInfoTopicName>
        <depthImageTopicName>image_raw</depthImageTopicName>
        <depthImageInfoTopicName>camera_left_info</depthImageInfoTopicName>
        <pointCloudTopicName>points</pointCloudTopicName>
        <frameName>camera_left_link_vis</frameName>
        <pointCloudCutoff>0.04</pointCloudCutoff>
        <distortionK1>0.0</distortionK1>
        <distortionK2>0.0</distortionK2>
        <distortionK3>0.0</distortionK3>
        <distortionT1>0.0</distortionT1>
        <distortionT2>0.0</distortionT2>
        <CxPrime>0</CxPrime>
        <Cx>0</Cx>
        <Cy>0</Cy>
        <focalLength>0</focalLength>
        <hackBaseline>0</hackBaseline>
      </plugin>
    </sensor>
  </gazebo>

<!--/////////////////////////////// Camera Back //////////////////////////////////-->

  <joint name="camera_back_joint_model" type="fixed">
      <child link="camera_back_link_model"/>
      <parent link="body"/>
      <origin xyz="-0.42882911 0.0 -0.0704022 " rpy="0.0 0.7853981633974483 3.141592653589793"/>
  </joint>
    
  <link name="camera_back_link_model">
    <!-- <visual>
      <origin xyz="0 0 0" rpy="0 0 0" />
      <geometry>
        <mesh filename="package://aidin8_sim/meshes/realsense_d435i.STL" />
      </geometry>
    </visual> -->
  </link>

  <joint name="camera_back_joint_per" type="fixed">
    <child link="camera_back_link_per"/>
    <parent link="camera_back_link_model"/>
    <origin xyz="0.02505 0.0 0.0" rpy="0.0 0.0 0.0"/>
  </joint>
    
  <link name="camera_back_link_per"/>

  <joint name="camera_back_joint_vis" type="fixed">
    <child link="camera_back_link_vis"/>
    <parent link="camera_back_link_per"/>
    <origin xyz="0.0 0.0 0.0" rpy="-1.57 0.0 -1.57"/>
  </joint>
    
  <link name="camera_back_link_vis"/>
      
  <gazebo reference="camera_back_link_per">
 <!--sensor name='camera_back1' type='camera'>
        <camera name="head_right1">
          <image>
            <width>64</width>
            <height>48</height>
          </image>
          <clip>
            <near>0.001</near>
            <far>300</far>
          </clip>
        </camera>
        <always_on>1</always_on>
        <update_rate>30.0</update_rate>
        <visualize>1</visualize>
        <plugin name="camera_back_controller" filename="libgazebo_ros_camera.so">

          <alwaysOn>true</alwaysOn>
          <updateRate>0.0</updateRate>
          <cameraName>camera_back1</cameraName>
          <imageTopicName>image_raw</imageTopicName>
          <cameraInfoTopicName>camera_info</cameraInfoTopicName>
          <frameName>/camera_back_link_vis</frameName>
          <hackBaseLine>0.07</hackBaseLine>
          <distortionK1>0.0</distortionK1>
          <distortionK2>0.0</distortionK2>
          <distortionK3>0.0</distortionK3>
          <distortionT1>0.0</distortionT1>
          <distortionT2>0.0</distortionT2>
        </plugin>
      </sensor-->
    <sensor name='camera_back' type='depth'>
      <camera name="camera_back">
        <horizontal_fov>1.5184364492</horizontal_fov>
        <image>
          <width>160</width> 
          <height>120</height> 
        </image>
        <clip>
          <near>0.02</near>
          <far>300</far>
        </clip>
      </camera>
      <always_on>1</always_on>
      <update_rate>30.0</update_rate>
      <visualize>1</visualize>
      <plugin name="camera_back_controller" filename="libgazebo_ros_openni_kinect.so">
        <robotNamespace></robotNamespace>
        <baseline>0.2</baseline>
        <alwaysOn>true</alwaysOn>
        <updateRate>30.0</updateRate>
        <cameraName>camera_back</cameraName>
        <imageTopicName>image_raw</imageTopicName>
        <cameraInfoTopicName>camera_back_info</cameraInfoTopicName>
        <depthImageTopicName>image_raw</depthImageTopicName>
        <depthImageInfoTopicName>camera_back_info</depthImageInfoTopicName>
        <pointCloudTopicName>points</pointCloudTopicName>
        <frameName>camera_back_link_vis</frameName>
        <pointCloudCutoff>0.04</pointCloudCutoff>
        <distortionK1>0.0</distortionK1>
        <distortionK2>0.0</distortionK2>
        <distortionK3>0.0</distortionK3>
        <distortionT1>0.0</distortionT1>
        <distortionT2>0.0</distortionT2>
        <CxPrime>0</CxPrime>
        <Cx>0</Cx>
        <Cy>0</Cy>
        <focalLength>0</focalLength>
        <hackBaseline>0</hackBaseline>
      </plugin>
    </sensor>
  </gazebo>

<!--/////////////////////////////// Camera Right //////////////////////////////////-->

  <joint name="camera_right_joint_model" type="fixed">
      <child link="camera_right_link_model"/>
      <parent link="body"/>
      <origin xyz="-0.074 -0.16720670557 -0.00864849 " rpy="0.0 1.1344640137963142 -1.5707963267948966"/>
  </joint>
    
  <link name="camera_right_link_model">
    <!-- <visual>
      <origin xyz="0 0 0" rpy="0 0 0" />
      <geometry>
        <mesh filename="package://aidin8_sim/meshes/realsense_d435i.STL" />
      </geometry>
    </visual> -->
  </link>

  <joint name="camera_right_joint_per" type="fixed">
    <child link="camera_right_link_per"/>
    <parent link="camera_right_link_model"/>
    <origin xyz="0.02505 0.0 0.0" rpy="0.0 0.0 0.0"/>
  </joint>
    
  <link name="camera_right_link_per"/>

  <joint name="camera_right_joint_vis" type="fixed">
    <child link="camera_right_link_vis"/>
    <parent link="camera_right_link_per"/>
    <origin xyz="0.0 0.0 0.0" rpy="-1.57 0.0 -1.57"/>
  </joint>
    
  <link name="camera_right_link_vis"/>
      
  <gazebo reference="camera_right_link_per">
 <!--sensor name='camera_right1' type='camera'>
        <camera name="head_right1">
          <image>
            <width>64</width>
            <height>48</height>
          </image>
          <clip>
            <near>0.001</near>
            <far>300</far>
          </clip>
        </camera>
        <always_on>1</always_on>
        <update_rate>30.0</update_rate>
        <visualize>1</visualize>
        <plugin name="camera_right_controller" filename="libgazebo_ros_camera.so">

          <alwaysOn>true</alwaysOn>
          <updateRate>0.0</updateRate>
          <cameraName>camera_right1</cameraName>
          <imageTopicName>image_raw</imageTopicName>
          <cameraInfoTopicName>camera_info</cameraInfoTopicName>
          <frameName>/camera_right_link_vis</frameName>
          <hackBaseLine>0.07</hackBaseLine>
          <distortionK1>0.0</distortionK1>
          <distortionK2>0.0</distortionK2>
          <distortionK3>0.0</distortionK3>
          <distortionT1>0.0</distortionT1>
          <distortionT2>0.0</distortionT2>
        </plugin>
      </sensor-->
    <sensor name='camera_right' type='depth'>
      <camera name="camera_right">
        <horizontal_fov>1.5184364492</horizontal_fov>
        <image>
          <width>160</width> 
          <height>120</height> 
        </image>
        <clip>
          <near>0.02</near>
          <far>300</far>
        </clip>
      </camera>
      <always_on>1</always_on>
      <update_rate>30.0</update_rate>
      <visualize>1</visualize>
      <plugin name="camera_right_controller" filename="libgazebo_ros_openni_kinect.so">
        <robotNamespace></robotNamespace>
        <baseline>0.2</baseline>
        <alwaysOn>true</alwaysOn>
        <updateRate>30.0</updateRate>
        <cameraName>camera_right</cameraName>
        <imageTopicName>image_raw</imageTopicName>
        <cameraInfoTopicName>camera_right_info</cameraInfoTopicName>
        <depthImageTopicName>image_raw</depthImageTopicName>
        <depthImageInfoTopicName>camera_right_info</depthImageInfoTopicName>
        <pointCloudTopicName>points</pointCloudTopicName>
        <frameName>camera_right_link_vis</frameName>
        <pointCloudCutoff>0.04</pointCloudCutoff>
        <distortionK1>0.0</distortionK1>
        <distortionK2>0.0</distortionK2>
        <distortionK3>0.0</distortionK3>
        <distortionT1>0.0</distortionT1>
        <distortionT2>0.0</distortionT2>
        <CxPrime>0</CxPrime>
        <Cx>0</Cx>
        <Cy>0</Cy>
        <focalLength>0</focalLength>
        <hackBaseline>0</hackBaseline>
      </plugin>
    </sensor>
  </gazebo>

  <!--//////////////////////////////// IMU ////////////////////////////////-->

  <!-- <link name="imu_link">
      <collision>
          <origin xyz="0 0 0" rpy="0 0 0"/>
          <geometry>
            <box size="0.1 0.1 0.1"/>
          </geometry>
      </collision>
      <visual>
          <origin xyz="0 0 0" rpy="0 0 0"/>
          <geometry>
            <box size="0.1 0.1 0.1"/>
          </geometry>
          <material name="orange"/>
      </visual>
      <inertial>
          <origin xyz="0 0 0" rpy="0 0 0"/>
          <mass value="0.1"/>
          <inertia
        ixx="0.00016667" ixy="0.0" ixz="0.0"
        iyy="0.00016667" iyz="0.0"
        izz="0.00016667"/>
      </inertial>
  </link>

  <joint name="imu_joint" type="fixed">
      <parent link="body"/>
      <child link="imu_link"/>
      <origin xyz="0 0 0" rpy="0 0 0"/>
      <axis xyz="0 0 0"/>
  </joint>

  <gazebo reference="imu_link">
    <gravity>true</gravity>
    <sensor name="imu_sensor" type="imu">
      <always_on>true</always_on>
      <update_rate>100</update_rate>
      <visualize>true</visualize>
      <topic>__default_topic__</topic>
      <plugin filename="libgazebo_ros_imu_sensor.so" name="imu_plugin">
        <topicName>IMU_sim</topicName>
        <bodyName>imu_link</bodyName>
        <updateRateHZ>100.0</updateRateHZ>
        <gaussianNoise>0.0</gaussianNoise>
        <xyzOffset>0 0 0</xyzOffset>
        <rpyOffset>0 0 0</rpyOffset>
        <frameName>imu_link</frameName>
        <initialOrientationAsReference>false</initialOrientationAsReference>
      </plugin>
      <pose>0 0 0 0 0 0</pose>
    </sensor>
  </gazebo> -->

  <!--//////////////////////////////// Aidin8 Plugin ////////////////////////////////-->
  <!--
  <gazebo>
    <plugin name="aidin8_plugin" filename="libaidin8_plugin.so">
    </plugin>
  </gazebo>
  -->
</robot>


