<?xml version="1.0" ?>
<robot name="rrbot">

  <material name="RRBOT/black">
    <color rgba="0.0 0.0 0.0 1.0"/>
  </material>
  <material name="RRBOT/blue">
    <color rgba="0.0 0.0 0.8 1.0"/>
  </material>
  <material name="RRBOT/green">
    <color rgba="0.0 0.8 0.0 1.0"/>
  </material>
  <material name="RRBOT/grey">
    <color rgba="0.2 0.2 0.2 1.0"/>
  </material>
  <material name="RRBOT/silver">
    <color rgba="0.913725490196 0.913725490196 0.847058823529 1.0"/>
  </material>
  <material name="RRBOT/orange">
    <color rgba="1.0 0.423529411765 0.0392156862745 1.0"/>
  </material>
  <material name="RRBOT/brown">
    <color rgba="0.870588235294 0.811764705882 0.764705882353 1.0"/>
  </material>
  <material name="RRBOT/red">
    <color rgba="0.8 0.0 0.0 1.0"/>
  </material>
  <material name="RRBOT/white">
    <color rgba="1.0 1.0 1.0 1.0"/>
  </material>
  
  
  <!-- "world" link -->
  <link name="world"/>
  <gazebo reference="world">
    <static>true</static>
  </gazebo>
  
  
  <!--////////////////////////////////   link    ////////////////////////////////-->
    
  <link name="rrbot_link1">
    <collision>
      <origin rpy="0 0 0" xyz="0 0 1.0"/>
      <geometry>
        <box size="0.1 0.1 2"/>
      </geometry>
    </collision>
    <visual>
      <origin rpy="0 0 0" xyz="0 0 1.0"/>
      <geometry>
        <box size="0.1 0.1 2"/>
      </geometry>
      <material name="RRBOT/orange"/>
    </visual>
    <inertial>
      <origin rpy="0 0 0" xyz="0 0 1.0"/>
      <mass value="1"/>
      <inertia ixx="1.0" ixy="0.0" ixz="0.0" iyy="1.0" iyz="0.0" izz="1.0"/>
    </inertial>
  </link>

  <link name="rrbot_link2">
    <collision>
      <origin rpy="0 0 0" xyz="0 0 0.45"/>
      <geometry>
        <box size="0.1 0.1 1"/>
      </geometry>
    </collision>
    <visual>
      <origin rpy="0 0 0" xyz="0 0 0.45"/>
      <geometry>
        <box size="0.1 0.1 1"/>
      </geometry>
      <material name="RRBOT/black"/>
    </visual>
    <inertial>
      <origin rpy="0 0 0" xyz="0 0 0.45"/>
      <mass value="1"/>
      <inertia ixx="1.0" ixy="0.0" ixz="0.0" iyy="1.0" iyz="0.0" izz="1.0"/>
    </inertial>
  </link>

  <link name="rrbot_link3">
    <collision>
      <origin rpy="0 0 0" xyz="0 0 0.45"/>
      <geometry>
        <box size="0.1 0.1 1"/>
      </geometry>
    </collision>
    <visual>
      <origin rpy="0 0 0" xyz="0 0 0.45"/>
      <geometry>
        <box size="0.1 0.1 1"/>
      </geometry>
      <material name="RRBOT/white"/>
    </visual>
    <inertial>
      <origin rpy="0 0 0" xyz="0 0 0.45"/>
      <mass value="1"/>
      <inertia ixx="1.0" ixy="0.0" ixz="0.0" iyy="1.0" iyz="0.0" izz="1.0"/>
    </inertial>
  </link>

  <gazebo reference="rrbot_link1">
    <material>Gazebo/Orange</material>
  </gazebo>
  
  <gazebo reference="rrbot_link2">
    <mu1>0.2</mu1>
    <mu2>0.2</mu2>
    <material>Gazebo/Black</material>
  </gazebo>
  
  <gazebo reference="rrbot_link3">
    <mu1>0.2</mu1>
    <mu2>0.2</mu2>
    <material>Gazebo/White</material>
  </gazebo>


  <!--////////////////////////////////   joint    ////////////////////////////////-->
  
  <joint name="rrbot_fixed" type="fixed">
    <origin rpy="0 0 0" xyz="0 0 0"/>
    <parent link="world"/>
    <child link="rrbot_link1"/>
  </joint>
  
  <joint name="rrbot_joint1" type="continuous">
    <parent link="rrbot_link1"/>
    <child link="rrbot_link2"/>
    <origin rpy="0 0 0" xyz="0 0.1 1.95"/>
    <axis xyz="0 1 0"/>
    <dynamics damping="0.7"/>
  </joint>

  <joint name="rrbot_joint2" type="continuous">
    <parent link="rrbot_link2"/>
    <child link="rrbot_link3"/>
    <origin rpy="0 0 0" xyz="0 0.1 0.9"/>
    <axis xyz="0 1 0"/>
    <dynamics damping="0.7"/>
  </joint>
  

  <!--/////////////////////////////   transmission    /////////////////////////////-->
<!--
  <transmission name="rrbot_tran1">
    <type>transmission_interface/SimpleTransmission</type>
    <joint name="rrbot_joint1">
      <hardwareInterface>PositionJointInterface</hardwareInterface>
    </joint>
    <actuator name="rrbot_motor1">
      <mechanicalReduction>1</mechanicalReduction>
    </actuator>
  </transmission>
  
  <transmission name="rrbot_tran2">
    <type>transmission_interface/SimpleTransmission</type>
    <joint name="rrbot_joint2">
      <hardwareInterface>PositionJointInterface</hardwareInterface>
    </joint>
    <actuator name="rrbot_motor2">
      <mechanicalReduction>1</mechanicalReduction>
    </actuator>
  </transmission>
-->

  <!--////////////////////////////////   plugin    ////////////////////////////////-->
  
  <!-- <gazebo>
    <plugin name="rrbot_plugin" filename="librrbot_plugin.so">
    </plugin>
  </gazebo>
   -->
</robot>

